Workbook

Sheet Dashboard
A1: AI Factory Dashboard — 32x Vera Rubin NVL72, Abu Dhabi, UAE
A2: Headline KPIs, all live-linked; edit assumptions on 'Control Panel & Inputs'
A4: KPI | B4: Value | C4: Unit | D4: Source Sheet
A5: Equity IRR (levered) | B5: ='Pro Forma Financials'!B36 -> 0.0034828395 | C5: % | D5: Pro Forma Financials
A6: Project IRR (unlevered) | B6: ='Pro Forma Financials'!B37 -> 0.047398178 | C6: % | D6: Pro Forma Financials
A7: Equity NPV @ hurdle rate | B7: ='Pro Forma Financials'!B38 -> -29426162 | C7: USD | D7: Pro Forma Financials
A8: MOIC | B8: ='Pro Forma Financials'!B39 -> 1.0154802 | C8: x | D8: Pro Forma Financials
A9: Payback Period | B9: ='Pro Forma Financials'!B40 -> 4.976705 | C9: years | D9: Pro Forma Financials
A10: Year 1 Gross Revenue | B10: ='Pro Forma Financials'!C$8 -> 75600000 | C10: USD | D10: Pro Forma Financials
A11: Year 1 EBITDA | B11: ='Pro Forma Financials'!C$14 -> 60755550 | C11: USD | D11: Pro Forma Financials
A12: Year 1 EBITDA Margin | B12: ='Pro Forma Financials'!C$15 -> 0.80364485 | C12: % | D12: Pro Forma Financials
A13: Minimum DSCR | B13: ='Pro Forma Financials'!B41 -> 0.96219738 | C13: x | D13: Pro Forma Financials
A14: Peak MLC vs ASHRAE 90.4 | B14: ='Thermal Hydraulics & MLC'!$B$23 -> 0.077831559 | C14: (limit 0.260) | D14: Thermal Hydraulics & MLC
A15: MLC Compliance Margin | B15: ='Thermal Hydraulics & MLC'!$B$25 -> 0.70064785 | C15: % | D15: Thermal Hydraulics & MLC
A16: Annual Facility Energy | B16: ='Thermal Hydraulics & MLC'!$B$28 -> 66124.161 | C16: MWh/yr | D16: Thermal Hydraulics & MLC
A17: Annual Carbon Emissions | B17: ='Thermal Hydraulics & MLC'!$B$30 -> 25788.423 | C17: tCO2/yr | D17: Thermal Hydraulics & MLC
A18: Annual Water Consumption | B18: ='Thermal Hydraulics & MLC'!$B$29 -> 9918.6242 | C18: m³/yr | D18: Thermal Hydraulics & MLC
A19: Total GPU Count | B19: ='Unit Economics & KPIs'!B5 -> 2304 | C19: GPUs | D19: Unit Economics & KPIs
A20: CapEx per GPU | B20: ='Unit Economics & KPIs'!B11 -> 142361.11 | C20: $/GPU | D20: Unit Economics & KPIs
A21: Blended Revenue per Sold GPU-hour | B21: ='Unit Economics & KPIs'!B8 -> 5.013238 | C21: $/GPU-hr | D21: Unit Economics & KPIs
A22: Cash Cost per M Tokens | B22: ='Unit Economics & KPIs'!B16 -> 0.13786986 | C22: $/M tok | D22: Unit Economics & KPIs
A23: Energy Cost as % of Revenue | B23: ='Unit Economics & KPIs'!B17 -> 0.047289497 | C23: % | D23: Unit Economics & KPIs
A24: Breakeven Power Tariff | B24: ='Unit Economics & KPIs'!B18 -> 1.1247279 | C24: $/kWh | D24: Unit Economics & KPIs
A25: Location / ASHRAE 169 Zone | B25: ='Control Panel & Inputs'!$C$5&" (zone "&'Control Panel & Inputs'!$C$6&")" -> Abu Dhabi, UAE (zone 1A) | D25: Control Panel & Inputs
A26: ASHRAE 90.4 MLC Limit (location) | B26: ='Control Panel & Inputs'!$C$7 -> 0.26 | C26: (design max) | D26: Control Panel & Inputs

Sheet Control Panel & Inputs
A1: NVIDIA Vera Rubin NVL72 AI Factory — Abu Dhabi, UAE
A2: Master Control Panel — edit only the yellow Value cells; every other sheet recalculates from them
A4: Category | B4: Parameter | C4: Value | D4: Unit | E4: Notes / Constraints
A5: Geographic & Climate | B5: Geo_Location | C5: Abu Dhabi, UAE | E5: Menu choice — drives ASHRAE zone, 90.4 MLC limit and N=20yr peaks
A6: Geographic & Climate | B6: ASHRAE_Climate_Zone | C6: =INDEX('ASHRAE Climate Library'!$B$5:$B$19,MATCH($C$5,'ASHRAE Climate Library'!$A$5:$A$19,0)) -> 1A | E6: Derived from location — ASHRAE 169 climate zone
A7: Geographic & Climate | B7: ASHRAE_MLC_Limit | C7: =INDEX('ASHRAE Climate Library'!$C$5:$C$19,MATCH($C$5,'ASHRAE Climate Library'!$A$5:$A$19,0)) -> 0.26 | E7: Derived from location — ASHRAE 90.4 max design MLC
A8: Geographic & Climate | B8: Peak_Ambient_DryBulb | C8: =INDEX('ASHRAE Climate Library'!$D$5:$D$19,MATCH($C$5,'ASHRAE Climate Library'!$A$5:$A$19,0)) -> 50 | D8: °C | E8: Derived from location — ASHRAE N=20yr extreme peak dry-bulb
A9: Geographic & Climate | B9: Coincident_WetBulb | C9: =INDEX('ASHRAE Climate Library'!$E$5:$E$19,MATCH($C$5,'ASHRAE Climate Library'!$A$5:$A$19,0)) -> 30 | D9: °C | E9: Derived from location — ASHRAE N=20yr peak wet-bulb
A10: Geographic & Climate | B10: Grid_Carbon_Intensity | C10: 0.39 | D10: kgCO2/kWh | E10: Assumption: Abu Dhabi grid avg (Barakah nuclear + gas + solar mix)
A11: Geographic & Climate | B11: Water_Usage_Effectiveness | C11: 0.15 | D11: L/kWh | E11: Assumption: closed-loop dry coolers, minimal adiabatic assist
A12: Technical Specs | B12: VR_Rack_Count | C12: 32 | D12: racks | E12: Vera Rubin NVL72 compute racks
A13: Technical Specs | B13: VR_Rack_Power_kW | C13: 227 | D13: kW/rack | E13: Compute & scale-up busbar load per VR rack
A14: Technical Specs | B14: VR_Cooling_Type | C14: Liquid | D14: Liquid/Air | E14: S45 direct-to-chip liquid loop
A15: Technical Specs | B15: Network_Rack_Count | C15: 6 | D15: racks | E15: Scale-out network fabric racks
A16: Technical Specs | B16: Network_Rack_Power_kW | C16: 100 | D16: kW/rack | E16: Switching + optics load per network rack
A17: Technical Specs | B17: Network_Cooling_Type | C17: Air | D17: Liquid/Air | E17: Hot-aisle containment air cooling
A18: Technical Specs | B18: Storage_Rack_Count | C18: 10 | D18: racks | E18: NVMe object/block storage racks
A19: Technical Specs | B19: Storage_Rack_Power_kW | C19: 40 | D19: kW/rack | E19: Load per storage rack
A20: Technical Specs | B20: Storage_Cooling_Type | C20: Air | D20: Liquid/Air | E20: Hot-aisle containment air cooling
A21: Technical Specs | B21: GPUs_Per_Rack | C21: 72 | D21: GPUs | E21: NVL72 = 72 Rubin GPUs per VR compute rack
A22: Technical Specs | B22: Liquid_Cooling_Overhead | C22: 0.05 | D22: kW/kW | E22: Cooling power per kW of liquid-cooled IT (CDU pumps, dry-cooler fans)
A23: Technical Specs | B23: Air_Cooling_Overhead | C23: 0.28 | D23: kW/kW | E23: Cooling power per kW of air-cooled IT (high-ambient chillers, CRAHs)
A24: Technical Specs | B24: Liquid_Supply_Temp_FWS | C24: 45 | D24: °C | E24: S45 direct-to-chip loop
A25: Technical Specs | B25: Liquid_Return_Temp_FWR | C25: 55 | D25: °C | E25: Facility water return — sets the loop delta-T
A26: Technical Specs | B26: Coolant_Specific_Heat | C26: 3.85 | D26: kJ/kg·K | E26: Assumption: PG25 water/glycol at ~50°C
A27: Technical Specs | B27: Coolant_Density | C27: 1.03 | D27: kg/L | E27: Assumption: PG25 mixture density
A28: Technical Specs | B28: Target_Annualized_PUE | C28: 1.08 | E28: Drives facility energy = IT energy x PUE
A29: Technical Specs | B29: Cluster_Utilization | C29: 0.85 | D29: % | E29: Assumption: avg power/capacity utilization of the fleet
A30: Technical Specs | B30: Uptime_Availability | C30: 0.995 | D30: % | E30: Assumption: contractual availability SLA
A31: Technical Specs | B31: Tokens_Per_GPU_Sec | C31: 1800 | D31: tok/s/GPU | E31: Assumption: blended inference throughput per Rubin GPU
A32: Technical Specs | B32: Token_Fleet_Share | C32: 0.3 | D32: % | E32: Share of fleet serving the API token market
A33: Financial & Fiscal | B33: Electricity_Tariff | C33: 0.06 | D33: $/kWh | E33: Abu Dhabi industrial rate (Year 1)
A34: Financial & Fiscal | B34: Tariff_Escalation | C34: 0.02 | D34: %/yr | E34: Assumption: annual power price escalation
A35: Financial & Fiscal | B35: CapEx_Initial | C35: 328000000 | D35: USD | E35: All-in benchmark midpoint: ~$91M facility (at $9.9-12.2M/MW) + 32 VR racks at ~$7.4M each (reported $6.0-8.8M). Set to ~$91M if IT is leased/vendor-financed.
A36: Financial & Fiscal | B36: Residual_Value_Pct | C36: 0.1 | D36: % | E36: Assumption: pre-tax residual recovery of CapEx at end of Year 5
A37: Financial & Fiscal | B37: Debt_Ratio | C37: 0.8 | D37: % | E37: User adjustable (50% - 80%)
A38: Financial & Fiscal | B38: Interest_Rate | C38: 0.065 | D38: % | E38: Senior debt facility rate
A39: Financial & Fiscal | B39: Debt_Tenor | C39: 5 | D39: Years | E39: Annual amortization schedule
A40: Financial & Fiscal | B40: Model_Horizon_Years | C40: 5 | D40: Years | E40: Pro forma & sensitivity horizon — STRUCTURAL: regenerate the workbook to change (year columns are created at build time)
... A52: Revenue Strategy | B52: Token_Volume_Growth | C52: 0.25 | D52: %/yr | E52: Token demand growth (partially offsets price decline)
...

Sheet ASHRAE Climate Library
A1: ASHRAE Climate & 90.4 Compliance Library
A2: Editable reference data — verify MLC limits against ASHRAE 90.4-2019 Table 6.5.1.1 and temperatures against ASHRAE Fundamentals n=20yr return-period extremes before design use
A4: Location | B4: ASHRAE 169 Zone | C4: ASHRAE 90.4 Max Design MLC | D4: N=20yr Peak Dry-Bulb (°C) | E4: N=20yr Peak Wet-Bulb (°C) | F4: Notes
A5: Abu Dhabi, UAE | B5: 1A | C5: 0.26 | D5: 50 | E5: 30 | F5: Project baseline; ASHRAE 169-2021 may reclassify as 0B
A6: Dubai, UAE | B6: 0B | C6: 0.28 | D6: 49.5 | E6: 31
A7: Riyadh, Saudi Arabia | B7: 0B | C7: 0.28 | D7: 49 | E7: 24 | F7: Dry extreme heat
A8: Singapore | B8: 0A | C8: 0.28 | D8: 36.5 | E8: 29.5 | F8: High wet-bulb year-round
A9: Mumbai, India | B9: 0A | C9: 0.28 | D9: 39.5 | E9: 30
A10: Phoenix, AZ, USA | B10: 2B | C10: 0.25 | D10: 48.5 | E10: 26.5
A11: Dallas, TX, USA | B11: 3A | C11: 0.21 | D11: 43.5 | E11: 27.5
A12: Ashburn, VA, USA | B12: 4A | C12: 0.19 | D12: 39 | E12: 27 | F12: N. Virginia hub
A13: Chicago, IL, USA | B13: 5A | C13: 0.16 | D13: 38.5 | E13: 27
A14: Frankfurt, Germany | B14: 5A | C14: 0.16 | D14: 37.5 | E14: 23
A15: Amsterdam, Netherlands | B15: 5A | C15: 0.16 | D15: 35 | E15: 22
A16: Dublin, Ireland | B16: 5A | C16: 0.16 | D16: 28.5 | E16: 19.5 | F16: Free-cooling friendly
A17: Oslo, Norway | B17: 6A | C17: 0.15 | D17: 32 | E17: 21
A18: Tokyo, Japan | B18: 3A | C18: 0.21 | D18: 37.5 | E18: 27.5
A19: Sydney, Australia | B19: 3A | C19: 0.21 | D19: 43 | E19: 24.5

Sheet Thermal Hydraulics & MLC
A1: Thermal Hydraulics & ASHRAE 90.4 Compliance Engine
A2: S45 closed-loop fluid dynamics, 3-stage trim cooling, and annual energy / water / carbon footprint
A4: Metric / Calculation Step | B4: Value | C4: Unit | D4: Notes
A5: VR Compute Rack Load | B5: ='Control Panel & Inputs'!$C$12*'Control Panel & Inputs'!$C$13 -> 7264 | C5: kW | D5: VR racks x kW/rack
A6: Network Rack Load | B6: ='Control Panel & Inputs'!$C$15*'Control Panel & Inputs'!$C$16 -> 600 | C6: kW | D6: Network racks x kW/rack
A7: Storage Rack Load | B7: ='Control Panel & Inputs'!$C$18*'Control Panel & Inputs'!$C$19 -> 400 | C7: kW | D7: Storage racks x kW/rack
A8: Total Combined IT Load | B8: =B5+B6+B7 -> 8264 | C8: kW | D8: VR compute + network + storage
A9: Liquid-Cooled IT Load | B9: =IF('Control Panel & Inputs'!$C$14="Liquid",B5,0)+IF('Control Panel & Inputs'!$C$17="Liquid",B6,0)+IF('Control Panel & Inputs'!$C$20="Liquid",B7,0) -> 7264 | C9: kW | D9: Sum of rack classes whose cooling type is 'Liquid'
A10: Air-Cooled IT Load | B10: =B8-B9 -> 1000 | C10: kW | D10: Total IT load minus liquid-cooled load
A11: Liquid-Cooled Rack Count | B11: =IF('Control Panel & Inputs'!$C$14="Liquid",'Control Panel & Inputs'!$C$12,0)+IF('Control Panel & Inputs'!$C$17="Liquid",'Control Panel & Inputs'!$C$15,0)+IF('Control Panel & Inputs'!$C$20="Liquid",'Control Panel & Inputs'!$C$18,0) -> 32 | C11: racks | D11: Racks on the S45 loop (cooling type = 'Liquid')
A12: S45 Loop Supply Temperature | B12: ='Control Panel & Inputs'!$C$24 -> 45 | C12: °C | D12: Facility Water Supply (FWS)
A13: S45 Loop Return Temperature | B13: ='Control Panel & Inputs'!$C$25 -> 55 | C13: °C | D13: Facility Water Return (FWR)
A14: S45 Loop Delta T | B14: =B13-B12 -> 10 | C14: °C | D14: Hydraulic temperature split
A15: S45 Liquid Flow Rate per VR Rack | B15: ='Control Panel & Inputs'!$C$13/('Control Panel & Inputs'!$C$27*'Control Panel & Inputs'!$C$26*B14)*60 -> 343.46236 | C15: LPM | D15: Physics: Q/(rho*Cp*dT)*60 — flow required to absorb one VR rack
A16: Total S45 Cluster Flow Rate | B16: =B9/('Control Panel & Inputs'!$C$27*'Control Panel & Inputs'!$C$26*B14)*60 -> 10990.796 | C16: LPM | D16: Physics: liquid-cooled load/(rho*Cp*dT)*60
A17: Peak Ambient Dry-Bulb (N=20yr) | B17: ='Control Panel & Inputs'!$C$8 -> 50 | C17: °C | D17: ASHRAE n=20yr extreme — derived from location
A18: Peak Wet-Bulb (N=20yr) | B18: ='Control Panel & Inputs'!$C$9 -> 30 | C18: °C | D18: ASHRAE n=20yr — derived from location
A19: S45 Peak Rejection Approach | B19: =B13-B17 -> 5 | C19: K | D19: FWR minus peak dry-bulb (positive = dry cooling viable)
A20: Liquid Loop Cooling Power | B20: =B9*'Control Panel & Inputs'!$C$22 -> 363.2 | C20: kW | D20: Liquid-cooled load x liquid cooling overhead input
A21: Air Loop Cooling Power | B21: =B10*'Control Panel & Inputs'!$C$23 -> 280 | C21: kW | D21: Air-cooled load x air cooling overhead input
A22: Total Cooling Peak Power | B22: =B20+B21 -> 643.2 | C22: kW | D22: Combined cooling power
A23: Peak Mechanical Load Component (MLC) | B23: =B22/B8 -> 0.077831559 | D23: Cooling power / total IT load
A24: ASHRAE 90.4 MLC Limit (from location) | B24: ='Control Panel & Inputs'!$C$7 -> 0.26 | D24: Max design MLC for the selected location's climate zone
A25: Safety Compliance Margin | B25: =(B24-B23)/B24 -> 0.70064785 | C25: % | D25: Operational margin under the location's 90.4 limit
A26: Average Utilized IT Power | B26: =B8*'Control Panel & Inputs'!$C$29*'Control Panel & Inputs'!$C$30 -> 6989.278 | C26: kW | D26: Total IT x utilization x uptime
A27: Annualized PUE | B27: ='Control Panel & Inputs'!$C$28 -> 1.08 | D27: Facility energy multiplier on IT energy
A28: Annual Facility Energy | B28: =B26*8760*B27/1000 -> 66124.161 | C28: MWh/yr | D28: Avg IT power x 8760h x PUE
A29: Annual Water Consumption | B29: =B28*'Control Panel & Inputs'!$C$11 -> 9918.6242 | C29: m³/yr | D29: Facility kWh x WUE
A30: Annual Carbon Emissions | B30: =B28*'Control Panel & Inputs'!$C$10 -> 25788.423 | C30: tCO2/yr | D30: Facility kWh x grid intensity

Sheet Pro Forma Financials
A1: 5-Year Leveraged Financial Model & Debt Amortization
A2: UAE corporate tax (9%) with GIDLR 30%-of-EBITDA interest cap, revenue ramp & escalations, full debt schedule and equity returns
A4: Line Item (USD) | B4: Year 0 | C4: Year 1 | D4: Year 2 | E4: Year 3 | F4: Year 4 | G4: Year 5
A5: Revenue Ramp Factor | B5: 0 | C5: ='Control Panel & Inputs'!$C$49 -> 0.9 | D5: 1 | E5: 1 | F5: 1 | G5: 1
A6: Lease Revenue | B6: 0 | C6: ='Control Panel & Inputs'!$C$47*POWER(1+'Control Panel & Inputs'!$C$50,0)*C5 -> 52920000 | D6: ='Control Panel & Inputs'!$C$47*POWER(1+'Control Panel & Inputs'!$C$50,1)*D5 -> 58800000 | E6: ='Control Panel & Inputs'!$C$47*POWER(1+'Control Panel & Inputs'!$C$50,2)*E5 -> 58800000 | F6: ='Control Panel & Inputs'!$C$47*POWER(1+'Control Panel & Inputs'!$C$50,3)*F5 -> 58800000 | G6: ='Control Panel & Inputs'!$C$47*POWER(1+'Control Panel & Inputs'!$C$50,4)*G5 -> 58800000
A7: Token Revenue | B7: 0 | C7: ='Control Panel & Inputs'!$C$48*POWER((1+'Control Panel & Inputs'!$C$52)*(1-'Control Panel & Inputs'!$C$51),0)*C5 -> 22680000 | D7: ='Control Panel & Inputs'!$C$48*POWER((1+'Control Panel & Inputs'!$C$52)*(1-'Control Panel & Inputs'!$C$51),1)*D5 -> 26775000 | E7: ='Control Panel & Inputs'!$C$48*POWER((1+'Control Panel & Inputs'!$C$52)*(1-'Control Panel & Inputs'!$C$51),2)*E5 -> 28448438 | F7: ='Control Panel & Inputs'!$C$48*POWER((1+'Control Panel & Inputs'!$C$52)*(1-'Control Panel & Inputs'!$C$51),3)*F5 -> 30226465 | G7: ='Control Panel & Inputs'!$C$48*POWER((1+'Control Panel & Inputs'!$C$52)*(1-'Control Panel & Inputs'!$C$51),4)*G5 -> 32115619
A8: Gross Annual Revenue | B8: 0 | C8: =C6+C7 -> 75600000 | D8: =D6+D7 -> 85575000 | E8: =E6+E7 -> 87248438 | F8: =F6+F7 -> 89026465 | G8: =G6+G7 -> 90915619
A9: Effective Power Tariff | B9: 0 | C9: ='Control Panel & Inputs'!$C$33*POWER(1+'Control Panel & Inputs'!$C$34,0) -> 0.06 | D9: ='Control Panel & Inputs'!$C$33*POWER(1+'Control Panel & Inputs'!$C$34,1) -> 0.0612 | E9: ='Control Panel & Inputs'!$C$33*POWER(1+'Control Panel & Inputs'!$C$34,2) -> 0.062424 | F9: ='Control Panel & Inputs'!$C$33*POWER(1+'Control Panel & Inputs'!$C$34,3) -> 0.06367248 | G9: ='Control Panel & Inputs'!$C$33*POWER(1+'Control Panel & Inputs'!$C$34,4) -> 0.06494593
A10: Annual Facility Energy (kWh) | B10: 0 | C10: ='Thermal Hydraulics & MLC'!$B$28*1000 -> 66124161 | D10: ='Thermal Hydraulics & MLC'!$B$28*1000 -> 66124161 | E10: ='Thermal Hydraulics & MLC'!$B$28*1000 -> 66124161 | F10: ='Thermal Hydraulics & MLC'!$B$28*1000 -> 66124161 | G10: ='Thermal Hydraulics & MLC'!$B$28*1000 -> 66124161
A11: Electricity Cost | B11: 0 | C11: =C10*C9 -> 3967449.7 | D11: =D10*D9 -> 4046798.7 | E11: =E10*E9 -> 4127734.6 | F11: =F10*F9 -> 4210289.3 | G11: =G10*G9 -> 4294495.1
A12: Fixed Non-Power OpEx | B12: 0 | C12: ='Control Panel & Inputs'!$C$45*POWER(1+'Control Panel & Inputs'!$C$46,0) -> 10877000 | D12: ='Control Panel & Inputs'!$C$45*POWER(1+'Control Panel & Inputs'!$C$46,1) -> 11203310 | E12: ='Control Panel & Inputs'!$C$45*POWER(1+'Control Panel & Inputs'!$C$46,2) -> 11539409 | F12: ='Control Panel & Inputs'!$C$45*POWER(1+'Control Panel & Inputs'!$C$46,3) -> 11885592 | G12: ='Control Panel & Inputs'!$C$45*POWER(1+'Control Panel & Inputs'!$C$46,4) -> 12242159
A13: Total Operational Expense (OpEx) | B13: 0 | C13: =C11+C12 -> 14844450 | D13: =D11+D12 -> 15250109 | E13: =E11+E12 -> 15667144 | F13: =F11+F12 -> 16095881 | G13: =G11+G12 -> 16536654
A14: EBITDA | B14: 0 | C14: =C8-C13 -> 60755550 | D14: =D8-D13 -> 70324891 | E14: =E8-E13 -> 71581294 | F14: =F8-F13 -> 72930584 | G14: =G8-G13 -> 74378964
A15: EBITDA Margin | B15: 0 | C15: =C14/C8 -> 0.80364485 | D15: =D14/D8 -> 0.82179248 | E15: =E14/E8 -> 0.82043066 | F15: =F14/F8 -> 0.81920117 | G15: =G14/G8 -> 0.81810986
A16: CapEx Initial Outlay | B16: ='Control Panel & Inputs'!$C$35 -> 328000000 | C16: 0 | D16: 0 | E16: 0 | F16: 0 | G16: 0
A17: Debt Financed Amount | B17: =B16*'Control Panel & Inputs'!$C$37 -> 262400000 | C17: 0 | D17: 0 | E17: 0 | F17: 0 | G17: 0
A18: Equity Outlay | B18: =B16-B17 -> 65600000 | C18: 0 | D18: 0 | E18: 0 | F18: 0 | G18: 0
A19: Beginning Debt Balance | B19: 0 | C19: =B17 -> 262400000 | D19: =C23 -> 2.163135e+08 | E19: =D23 -> 1.6723137e+08 | F19: =E23 -> 1.1495891e+08 | G19: =F23 -> 59288735
A20: Annual Debt Service (P+I) | B20: 0 | C20: =IF(1<='Control Panel & Inputs'!$C$39,-PMT('Control Panel & Inputs'!$C$38,'Control Panel & Inputs'!$C$39,B17),0) -> 63142503 | D20: =IF(2<='Control Panel & Inputs'!$C$39,-PMT('Control Panel & Inputs'!$C$38,'Control Panel & Inputs'!$C$39,B17),0) -> 63142503 | E20: =IF(3<='Control Panel & Inputs'!$C$39,-PMT('Control Panel & Inputs'!$C$38,'Control Panel & Inputs'!$C$39,B17),0) -> 63142503 | F20: =IF(4<='Control Panel & Inputs'!$C$39,-PMT('Control Panel & Inputs'!$C$38,'Control Panel & Inputs'!$C$39,B17),0) -> 63142503 | G20: =IF(5<='Control Panel & Inputs'!$C$39,-PMT('Control Panel & Inputs'!$C$38,'Control Panel & Inputs'!$C$39,B17),0) -> 63142503
A21: Interest Expense | B21: 0 | C21: =C19*'Control Panel & Inputs'!$C$38 -> 17056000 | D21: =D19*'Control Panel & Inputs'!$C$38 -> 14060377 | E21: =E19*'Control Panel & Inputs'!$C$38 -> 10870039 | F21: =F19*'Control Panel & Inputs'!$C$38 -> 7472329.1 | G21: =G19*'Control Panel & Inputs'!$C$38 -> 3853767.8
A22: Debt Principal Payment | B22: 0 | C22: =C20-C21 -> 46086503 | D22: =D20-D21 -> 49082125 | E22: =E20-E21 -> 52272463 | F22: =F20-F21 -> 55670174 | G22: =G20-G21 -> 59288735
A23: Ending Debt Balance | B23: 0 | C23: =C19-C22 -> 2.163135e+08 | D23: =D19-D22 -> 1.6723137e+08 | E23: =E19-E22 -> 1.1495891e+08 | F23: =F19-F22 -> 59288735 | G23: =G19-G22 -> 0
A24: Depreciation (Straight Line) | B24: 0 | C24: =IF(1<='Control Panel & Inputs'!$C$41,B16/'Control Panel & Inputs'!$C$41,0) -> 65600000 | D24: =IF(2<='Control Panel & Inputs'!$C$41,B16/'Control Panel & Inputs'!$C$41,0) -> 65600000 | E24: =IF(3<='Control Panel & Inputs'!$C$41,B16/'Control Panel & Inputs'!$C$41,0) -> 65600000 | F24: =IF(4<='Control Panel & Inputs'!$C$41,B16/'Control Panel & Inputs'!$C$41,0) -> 65600000 | G24: =IF(5<='Control Panel & Inputs'!$C$41,B16/'Control Panel & Inputs'!$C$41,0) -> 65600000
A25: GIDLR Deductible Interest | B25: 0 | C25: =MIN(C21,'Control Panel & Inputs'!$C$43*C14) -> 17056000 | D25: =MIN(D21,'Control Panel & Inputs'!$C$43*D14) -> 14060377 | E25: =MIN(E21,'Control Panel & Inputs'!$C$43*E14) -> 10870039 | F25: =MIN(F21,'Control Panel & Inputs'!$C$43*F14) -> 7472329.1 | G25: =MIN(G21,'Control Panel & Inputs'!$C$43*G14) -> 3853767.8
A26: Taxable Income | B26: 0 | C26: =C14-C24-C25 -> -21900450 | D26: =D14-D24-D25 -> -9335486 | E26: =E14-E24-E25 -> -4888745.6 | F26: =F14-F24-F25 -> -141745.13 | G26: =G14-G24-G25 -> 4925196.7
A27: UAE Corporate Tax | B27: 0 | C27: =MAX(0,C26)*'Control Panel & Inputs'!$C$42 -> 0 | D27: =MAX(0,D26)*'Control Panel & Inputs'!$C$42 -> 0 | E27: =MAX(0,E26)*'Control Panel & Inputs'!$C$42 -> 0 | F27: =MAX(0,F26)*'Control Panel & Inputs'!$C$42 -> 0 | G27: =MAX(0,G26)*'Control Panel & Inputs'!$C$42 -> 443267.7
A28: Residual Value Recovery | B28: 0 | C28: 0 | D28: 0 | E28: 0 | F28: 0 | G28: ='Control Panel & Inputs'!$C$35*'Control Panel & Inputs'!$C$36 -> 32800000
A29: Leveraged Free Cash Flow (FCFE) | B29: =-B18 -> -65600000 | C29: =C14-C20-C27+C28 -> -2386952.3 | D29: =D14-D20-D27+D28 -> 7182388.7 | E29: =E14-E20-E27+E28 -> 8438790.9 | F29: =F14-F20-F27+F28 -> 9788081.3 | G29: =G14-G20-G27+G28 -> 43593194
A30: Cumulative FCFE | B30: =B29 -> -65600000 | C30: =B30+C29 -> -67986952 | D30: =C30+D29 -> -60804564 | E30: =D30+E29 -> -52365773 | F30: =E30+F29 -> -42577692 | G30: =F30+G29 -> 1015502.5
A31: Debt Service Coverage Ratio (DSCR) | B31: 0 | C31: =IF(C20=0,"",C14/C20) -> 0.96219738 | D31: =IF(D20=0,"",D14/D20) -> 1.1137489 | E31: =IF(E20=0,"",E14/E20) -> 1.1336468 | F31: =IF(F20=0,"",F14/F20) -> 1.1550157 | G31: =IF(G20=0,"",G14/G20) -> 1.177954
A32: Unlevered Tax (no interest shield) | B32: 0 | C32: =MAX(0,C14-C24)*'Control Panel & Inputs'!$C$42 -> 0 | D32: =MAX(0,D14-D24)*'Control Panel & Inputs'!$C$42 -> 425240.22 | E32: =MAX(0,E14-E24)*'Control Panel & Inputs'!$C$42 -> 538316.42 | F32: =MAX(0,F14-F24)*'Control Panel & Inputs'!$C$42 -> 659752.55 | G32: =MAX(0,G14-G24)*'Control Panel & Inputs'!$C$42 -> 790106.8
A33: Unlevered Free Cash Flow (FCFF) | B33: =-B16 -> -328000000 | C33: =C14-C32+C28 -> 60755550 | D33: =D14-D32+D28 -> 69899651 | E33: =E14-E32+E28 -> 71042977 | F33: =F14-F32+F28 -> 72270831 | G33: =G14-G32+G28 -> 1.0638886e+08
A35: Equity Returns Summary
A36: Equity IRR (levered) | B36: =IRR(B29:G29) -> 0.0034828395
A37: Project IRR (unlevered) | B37: =IRR(B33:G33) -> 0.047398178
A38: Equity NPV @ hurdle rate | B38: =B29+NPV('Control Panel & Inputs'!$C$44,C29:G29) -> -29426162
A39: MOIC (total distributions / equity) | B39: =SUM(C29:G29)/-B29 -> 1.0154802
A40: Payback Period | B40: =IFERROR(COUNTIF(B30:G30,"<0")-1+ABS(INDEX(B30:G30,COUNTIF(B30:G30,"<0")))/INDEX(B29:G29,COUNTIF(B30:G30,"<0")+1),">5 yrs") -> 4.976705
A41: Minimum DSCR | B41: =MIN(C31:G31) -> 0.96219738
A42: Average DSCR | B42: =AVERAGE(C31:G31) -> 1.1085126

Sheet Unit Economics & KPIs
A1: Unit Economics & Operational KPIs
A2: GPU-hour and token-level economics (steady-state Year 2, post-ramp) — all cells formula-driven
A4: KPI | B4: Value | C4: Unit | D4: Derivation
A5: Total GPU Count | B5: ='Control Panel & Inputs'!$C$12*'Control Panel & Inputs'!$C$21 -> 2304 | C5: GPUs | D5: Racks x GPUs per rack
A6: Available GPU-hours / yr | B6: =B5*8760*'Control Panel & Inputs'!$C$30 -> 20082125 | C6: GPU-hrs | D6: GPUs x 8760h x uptime
A7: Sold GPU-hours / yr | B7: =B6*'Control Panel & Inputs'!$C$29 -> 17069806 | C7: GPU-hrs | D7: Available x utilization
A8: Blended Revenue per Sold GPU-hour | B8: ='Pro Forma Financials'!D$8/B7 -> 5.013238 | C8: $/GPU-hr | D8: Year 2 gross revenue / sold GPU-hours
A9: Cash OpEx per Sold GPU-hour | B9: ='Pro Forma Financials'!D$13/B7 -> 0.89339671 | C9: $/GPU-hr | D9: Year 2 total OpEx / sold GPU-hours
A10: EBITDA per Sold GPU-hour | B10: =B8-B9 -> 4.1198413 | C10: $/GPU-hr | D10: Revenue minus cash OpEx per GPU-hour
A11: CapEx per GPU | B11: ='Control Panel & Inputs'!$C$35/B5 -> 142361.11 | C11: $/GPU | D11: Total CapEx / GPU count
A12: CapEx per MW of IT Load | B12: ='Control Panel & Inputs'!$C$35/('Thermal Hydraulics & MLC'!$B$8/1000) -> 39690223 | C12: $/MW | D12: Total CapEx / total IT MW
A13: Revenue per MW of IT Load | B13: ='Pro Forma Financials'!D$8/('Thermal Hydraulics & MLC'!$B$8/1000) -> 10355155 | C13: $/MW/yr | D13: Year 2 revenue / total IT MW
A14: Annual Token Capacity (token fleet) | B14: =B5*'Control Panel & Inputs'!$C$32*'Control Panel & Inputs'!$C$31*3600*8760*'Control Panel & Inputs'!$C$29*'Control Panel & Inputs'!$C$30/1000000000000 -> 33.183703 | C14: T tokens/yr | D14: Token-fleet GPUs x tok/s x seconds x utilization x uptime
A15: Implied Realized Price per M Tokens | B15: ='Pro Forma Financials'!D$7/(B14*1000000) -> 0.80687198 | C15: $/M tok | D15: Year 2 token revenue / token capacity
A16: Cash Cost per M Tokens | B16: ='Pro Forma Financials'!D$13*'Control Panel & Inputs'!$C$32/(B14*1000000) -> 0.13786986 | C16: $/M tok | D16: Token-fleet share of Year 2 OpEx / token capacity
A17: Energy Cost as % of Revenue | B17: ='Pro Forma Financials'!D$11/'Pro Forma Financials'!D$8 -> 0.047289497 | C17: % | D17: Year 2 electricity / Year 2 revenue
A18: Breakeven Power Tariff (EBITDA = 0) | B18: =('Pro Forma Financials'!D$8-'Pro Forma Financials'!D$12)/'Pro Forma Financials'!D$10 -> 1.1247279 | C18: $/kWh | D18: (Year 2 revenue - fixed OpEx) / annual kWh
A19: Min Revenue for 1.00x DSCR | B19: ='Pro Forma Financials'!D$20+'Pro Forma Financials'!D$13 -> 78392611 | C19: USD/yr | D19: Debt service + Year 2 OpEx
A20: Revenue Headroom above 1.00x DSCR | B20: =1-B19/'Pro Forma Financials'!D$8 -> 0.083930922 | C20: % | D20: 1 - min revenue / Year 2 revenue

Sheet Sensitivity Engine
A1: Sensitivity Engine — 16 Live Scenarios over 5 Years
A2: Each row re-runs the full leveraged model (debt schedule, GIDLR tax cap, residual value) for one tariff x debt-ratio combination
A4: Scenario | B4: Tariff $/kWh | C4: Debt % | D4: Debt $ | E4: Equity $ | F4: Debt Service | G4: Y0 FCFE | H4: Y1 FCFE | I4: Y2 FCFE | J4: Y3 FCFE | K4: Y4 FCFE | L4: Y5 FCFE | M4: Equity IRR | N4: Avg DSCR
A5: $0.04/kWh @ 50% debt | B5: 0.04 | C5: 0.5 | D5: ='Control Panel & Inputs'!$C$35*$C5 -> 164000000 | E5: ='Control Panel & Inputs'!$C$35-$D5 -> 164000000 | F5: =-PMT('Control Panel & Inputs'!$C$38,'Control Panel & Inputs'!$C$39,$D5) -> 39464064 | G5: =-$E5 -> -164000000 | H5: =B23-IF(1<='Control Panel & Inputs'!$C$39,$F5,0)-MAX(0,B23-IF(1<='Control Panel & Inputs'!$C$41,'Control Panel & Inputs'!$C$35/'Control Panel & Inputs'!$C$41,0)-MIN(IF(1<='Control Panel & Inputs'!$C$39,-IPMT('Control Panel & Inputs'!$C$38,1,'Control Panel & Inputs'!$C$39,$D5),0),'Control Panel & Inputs'!$C$43*B23))*'Control Panel & Inputs'!$C$42 -> 22613969 | I5: =C23-IF(2<='Control Panel & Inputs'!$C$39,$F5,0)-MAX(0,C23-IF(2<='Control Panel & Inputs'!$C$41,'Control Panel & Inputs'!$C$35/'Control Panel & Inputs'!$C$41,0)-MIN(IF(2<='Control Panel & Inputs'!$C$39,-IPMT('Control Panel & Inputs'!$C$38,2,'Control Panel & Inputs'!$C$39,$D5),0),'Control Panel & Inputs'!$C$43*C23))*'Control Panel & Inputs'!$C$42 -> 32209760 | J5: =D23-IF(3<='Control Panel & Inputs'!$C$39,$F5,0)-MAX(0,D23-IF(3<='Control Panel & Inputs'!$C$41,'Control Panel & Inputs'!$C$35/'Control Panel & Inputs'!$C$41,0)-MIN(IF(3<='Control Panel & Inputs'!$C$39,-IPMT('Control Panel & Inputs'!$C$38,3,'Control Panel & Inputs'!$C$39,$D5),0),'Control Panel & Inputs'!$C$43*D23))*'Control Panel & Inputs'!$C$42 -> 33442432 | K5: =E23-IF(4<='Control Panel & Inputs'!$C$39,$F5,0)-MAX(0,E23-IF(4<='Control Panel & Inputs'!$C$41,'Control Panel & Inputs'!$C$35/'Control Panel & Inputs'!$C$41,0)-MIN(IF(4<='Control Panel & Inputs'!$C$39,-IPMT('Control Panel & Inputs'!$C$38,4,'Control Panel & Inputs'!$C$39,$D5),0),'Control Panel & Inputs'!$C$43*E23))*'Control Panel & Inputs'!$C$42 -> 34504207 | L5: =F23-IF(5<='Control Panel & Inputs'!$C$39,$F5,0)-MAX(0,F23-IF(5<='Control Panel & Inputs'!$C$41,'Control Panel & Inputs'!$C$35/'Control Panel & Inputs'!$C$41,0)-MIN(IF(5<='Control Panel & Inputs'!$C$39,-IPMT('Control Panel & Inputs'!$C$38,5,'Control Panel & Inputs'!$C$39,$D5),0),'Control Panel & Inputs'!$C$43*F23))*'Control Panel & Inputs'!$C$42+'Control Panel & Inputs'!$C$35*'Control Panel & Inputs'!$C$36 -> 68444231 | M5: =IRR(G5:L5) -> 0.045558179 | N5: =AVERAGE(B23:F23)/$F5 -> 1.8084987
A6: $0.04/kWh @ 60% debt | B6: 0.04 | C6: 0.6 | D6: ='Control Panel & Inputs'!$C$35*$C6 -> 196800000 | E6: ='Control Panel & Inputs'!$C$35-$D6 -> 131200000 | F6: =-PMT('Control Panel & Inputs'!$C$38,'Control Panel & Inputs'!$C$39,$D6) -> 47356877 | G6: =-$E6 -> -131200000 | H6: =B24-IF(1<='Control Panel & Inputs'!$C$39,$F6,0)-MAX(0,B24-IF(1<='Control Panel & Inputs'!$C$41,'Control Panel & Inputs'!$C$35/'Control Panel & Inputs'!$C$41,0)-MIN(IF(1<='Control Panel & Inputs'!$C$39,-IPMT('Control Panel & Inputs'!$C$38,1,'Control Panel & Inputs'!$C$39,$D6),0),'Control Panel & Inputs'!$C$43*B24))*'Control Panel & Inputs'!$C$42 -> 14721157 | I6: =C24-IF(2<='Control Panel & Inputs'!$C$39,$F6,0)-MAX(0,C24-IF(2<='Control Panel & Inputs'!$C$41,'Control Panel & Inputs'!$C$35/'Control Panel & Inputs'!$C$41,0)-MIN(IF(2<='Control Panel & Inputs'!$C$39,-IPMT('Control Panel & Inputs'!$C$38,2,'Control Panel & Inputs'!$C$39,$D6),0),'Control Panel & Inputs'!$C$43*C24))*'Control Panel & Inputs'!$C$42 -> 24316947 | J6: =D24-IF(3<='Control Panel & Inputs'!$C$39,$F6,0)-MAX(0,D24-IF(3<='Control Panel & Inputs'!$C$41,'Control Panel & Inputs'!$C$35/'Control Panel & Inputs'!$C$41,0)-MIN(IF(3<='Control Panel & Inputs'!$C$39,-IPMT('Control Panel & Inputs'!$C$38,3,'Control Panel & Inputs'!$C$39,$D6),0),'Control Panel & Inputs'!$C$43*D24))*'Control Panel & Inputs'!$C$42 -> 25600328 | K6: =E24-IF(4<='Control Panel & Inputs'!$C$39,$F6,0)-MAX(0,E24-IF(4<='Control Panel & Inputs'!$C$41,'Control Panel & Inputs'!$C$35/'Control Panel & Inputs'!$C$41,0)-MIN(IF(4<='Control Panel & Inputs'!$C$39,-IPMT('Control Panel & Inputs'!$C$38,4,'Control Panel & Inputs'!$C$39,$D6),0),'Control Panel & Inputs'!$C$43*E24))*'Control Panel & Inputs'!$C$42 -> 26695458 | L6: =F24-IF(5<='Control Panel & Inputs'!$C$39,$F6,0)-MAX(0,F24-IF(5<='Control Panel & Inputs'!$C$41,'Control Panel & Inputs'!$C$35/'Control Panel & Inputs'!$C$41,0)-MIN(IF(5<='Control Panel & Inputs'!$C$39,-IPMT('Control Panel & Inputs'!$C$38,5,'Control Panel & Inputs'!$C$39,$D6),0),'Control Panel & Inputs'!$C$43*F24))*'Control Panel & Inputs'!$C$42+'Control Panel & Inputs'!$C$35*'Control Panel & Inputs'!$C$36 -> 60594773 | M6: =IRR(G6:L6) -> 0.041831199 | N6: =AVERAGE(B24:F24)/$F6 -> 1.5070822
A7: $0.04/kWh @ 70% debt | B7: 0.04 | C7: 0.7 | D7: ='Control Panel & Inputs'!$C$35*$C7 -> 229600000 | E7: ='Control Panel & Inputs'!$C$35-$D7 -> 98400000 | F7: =-PMT('Control Panel & Inputs'!$C$38,'Control Panel & Inputs'!$C$39,$D7) -> 55249690 | G7: =-$E7 -> -98400000 | H7: =B25-IF(1<='Control Panel & Inputs'!$C$39,$F7,0)-MAX(0,B25-IF(1<='Control Panel & Inputs'!$C$41,'Control Panel & Inputs'!$C$35/'Control Panel & Inputs'!$C$41,0)-MIN(IF(1<='Control Panel & Inputs'!$C$39,-IPMT('Control Panel & Inputs'!$C$38,1,'Control Panel & Inputs'!$C$39,$D7),0),'Control Panel & Inputs'!$C$43*B25))*'Control Panel & Inputs'!$C$42 -> 6828343.7 | I7: =C25-IF(2<='Control Panel & Inputs'!$C$39,$F7,0)-MAX(0,C25-IF(2<='Control Panel & Inputs'!$C$41,'Control Panel & Inputs'!$C$35/'Control Panel & Inputs'!$C$41,0)-MIN(IF(2<='Control Panel & Inputs'!$C$39,-IPMT('Control Panel & Inputs'!$C$38,2,'Control Panel & Inputs'!$C$39,$D7),0),'Control Panel & Inputs'!$C$43*C25))*'Control Panel & Inputs'!$C$42 -> 16424134 | J7: =D25-IF(3<='Control Panel & Inputs'!$C$39,$F7,0)-MAX(0,D25-IF(3<='Control Panel & Inputs'!$C$41,'Control Panel & Inputs'!$C$35/'Control Panel & Inputs'!$C$41,0)-MIN(IF(3<='Control Panel & Inputs'!$C$39,-IPMT('Control Panel & Inputs'!$C$38,3,'Control Panel & Inputs'!$C$39,$D7),0),'Control Panel & Inputs'!$C$43*D25))*'Control Panel & Inputs'!$C$42 -> 17707515 | K7: =E25-IF(4<='Control Panel & Inputs'!$C$39,$F7,0)-MAX(0,E25-IF(4<='Control Panel & Inputs'!$C$41,'Control Panel & Inputs'!$C$35/'Control Panel & Inputs'!$C$41,0)-MIN(IF(4<='Control Panel & Inputs'!$C$39,-IPMT('Control Panel & Inputs'!$C$38,4,'Control Panel & Inputs'!$C$39,$D7),0),'Control Panel & Inputs'!$C$43*E25))*'Control Panel & Inputs'!$C$42 -> 18886709 | L7: =F25-IF(5<='Control Panel & Inputs'!$C$39,$F7,0)-MAX(0,F25-IF(5<='Control Panel & Inputs'!$C$41,'Control Panel & Inputs'!$C$35/'Control Panel & Inputs'!$C$41,0)-MIN(IF(5<='Control Panel & Inputs'!$C$39,-IPMT('Control Panel & Inputs'!$C$38,5,'Control Panel & Inputs'!$C$39,$D7),0),'Control Panel & Inputs'!$C$43*F25))*'Control Panel & Inputs'!$C$42+'Control Panel & Inputs'!$C$35*'Control Panel & Inputs'!$C$36 -> 52745316 | M7: =IRR(G7:L7) -> 0.036027847 | N7: =AVERAGE(B25:F25)/$F7 -> 1.2917848
A8: $0.04/kWh @ 80% debt | B8: 0.04 | C8: 0.8 | D8: ='Control Panel & Inputs'!$C$35*$C8 -> 262400000 | E8: ='Control Panel & Inputs'!$C$35-$D8 -> 65600000 | F8: =-PMT('Control Panel & Inputs'!$C$38,'Control Panel & Inputs'!$C$39,$D8) -> 63142503 | G8: =-$E8 -> -65600000 | H8: =B26-IF(1<='Control Panel & Inputs'!$C$39,$F8,0)-MAX(0,B26-IF(1<='Control Panel & Inputs'!$C$41,'Control Panel & Inputs'!$C$35/'Control Panel & Inputs'!$C$41,0)-MIN(IF(1<='Control Panel & Inputs'!$C$39,-IPMT('Control Panel & Inputs'!$C$38,1,'Control Panel & Inputs'!$C$39,$D8),0),'Control Panel & Inputs'!$C$43*B26))*'Control Panel & Inputs'!$C$42 -> -1064469.1 | I8: =C26-IF(2<='Control Panel & Inputs'!$C$39,$F8,0)-MAX(0,C26-IF(2<='Control Panel & Inputs'!$C$41,'Control Panel & Inputs'!$C$35/'Control Panel & Inputs'!$C$41,0)-MIN(IF(2<='Control Panel & Inputs'!$C$39,-IPMT('Control Panel & Inputs'!$C$38,2,'Control Panel & Inputs'!$C$39,$D8),0),'Control Panel & Inputs'!$C$43*C26))*'Control Panel & Inputs'!$C$42 -> 8531321.6 | J8: =D26-IF(3<='Control Panel & Inputs'!$C$39,$F8,0)-MAX(0,D26-IF(3<='Control Panel & Inputs'!$C$41,'Control Panel & Inputs'!$C$35/'Control Panel & Inputs'!$C$41,0)-MIN(IF(3<='Control Panel & Inputs'!$C$39,-IPMT('Control Panel & Inputs'!$C$38,3,'Control Panel & Inputs'!$C$39,$D8),0),'Control Panel & Inputs'!$C$43*D26))*'Control Panel & Inputs'!$C$42 -> 9814702.4 | K8: =E26-IF(4<='Control Panel & Inputs'!$C$39,$F8,0)-MAX(0,E26-IF(4<='Control Panel & Inputs'!$C$41,'Control Panel & Inputs'!$C$35/'Control Panel & Inputs'!$C$41,0)-MIN(IF(4<='Control Panel & Inputs'!$C$39,-IPMT('Control Panel & Inputs'!$C$38,4,'Control Panel & Inputs'!$C$39,$D8),0),'Control Panel & Inputs'!$C$43*E26))*'Control Panel & Inputs'!$C$42 -> 11077959 | L8: =F26-IF(5<='Control Panel & Inputs'!$C$39,$F8,0)-MAX(0,F26-IF(5<='Control Panel & Inputs'!$C$41,'Control Panel & Inputs'!$C$35/'Control Panel & Inputs'!$C$41,0)-MIN(IF(5<='Control Panel & Inputs'!$C$39,-IPMT('Control Panel & Inputs'!$C$38,5,'Control Panel & Inputs'!$C$39,$D8),0),'Control Panel & Inputs'!$C$43*F26))*'Control Panel & Inputs'!$C$42+'Control Panel & Inputs'!$C$35*'Control Panel & Inputs'!$C$36 -> 44895858 | M8: =IRR(G8:L8) -> 0.026145349 | N8: =AVERAGE(B26:F26)/$F8 -> 1.1303117
A9: $0.06/kWh @ 50% debt | B9: 0.06 | C9: 0.5 | D9: ='Control Panel & Inputs'!$C$35*$C9 -> 164000000 | E9: ='Control Panel & Inputs'!$C$35-$D9 -> 164000000 | F9: =-PMT('Control Panel & Inputs'!$C$38,'Control Panel & Inputs'!$C$39,$D9) -> 39464064 | G9: =-$E9 -> -164000000 | H9: =B27-IF(1<='Control Panel & Inputs'!$C$39,$F9,0)-MAX(0,B27-IF(1<='Control Panel & Inputs'!$C$41,'Control Panel & Inputs'!$C$35/'Control Panel & Inputs'!$C$41,0)-MIN(IF(1<='Control Panel & Inputs'!$C$39,-IPMT('Control Panel & Inputs'!$C$38,1,'Control Panel & Inputs'!$C$39,$D9),0),'Control Panel & Inputs'!$C$43*B27))*'Control Panel & Inputs'!$C$42 -> 21291486 | I9: =C27-IF(2<='Control Panel & Inputs'!$C$39,$F9,0)-MAX(0,C27-IF(2<='Control Panel & Inputs'!$C$41,'Control Panel & Inputs'!$C$35/'Control Panel & Inputs'!$C$41,0)-MIN(IF(2<='Control Panel & Inputs'!$C$39,-IPMT('Control Panel & Inputs'!$C$38,2,'Control Panel & Inputs'!$C$39,$D9),0),'Control Panel & Inputs'!$C$43*C27))*'Control Panel & Inputs'!$C$42 -> 30860827 | J9: =D27-IF(3<='Control Panel & Inputs'!$C$39,$F9,0)-MAX(0,D27-IF(3<='Control Panel & Inputs'!$C$41,'Control Panel & Inputs'!$C$35/'Control Panel & Inputs'!$C$41,0)-MIN(IF(3<='Control Panel & Inputs'!$C$39,-IPMT('Control Panel & Inputs'!$C$38,3,'Control Panel & Inputs'!$C$39,$D9),0),'Control Panel & Inputs'!$C$43*D27))*'Control Panel & Inputs'!$C$42 -> 32117229 | K9: =E27-IF(4<='Control Panel & Inputs'!$C$39,$F9,0)-MAX(0,E27-IF(4<='Control Panel & Inputs'!$C$41,'Control Panel & Inputs'!$C$35/'Control Panel & Inputs'!$C$41,0)-MIN(IF(4<='Control Panel & Inputs'!$C$39,-IPMT('Control Panel & Inputs'!$C$38,4,'Control Panel & Inputs'!$C$39,$D9),0),'Control Panel & Inputs'!$C$43*E27))*'Control Panel & Inputs'!$C$42 -> 33227086 | L9: =F27-IF(5<='Control Panel & Inputs'!$C$39,$F9,0)-MAX(0,F27-IF(5<='Control Panel & Inputs'!$C$41,'Control Panel & Inputs'!$C$35/'Control Panel & Inputs'!$C$41,0)-MIN(IF(5<='Control Panel & Inputs'!$C$39,-IPMT('Control Panel & Inputs'!$C$38,5,'Control Panel & Inputs'!$C$39,$D9),0),'Control Panel & Inputs'!$C$43*F27))*'Control Panel & Inputs'!$C$42+'Control Panel & Inputs'!$C$35*'Control Panel & Inputs'!$C$36 -> 67141568 | M9: =IRR(G9:L9) -> 0.034697533 | N9: =AVERAGE(B27:F27)/$F9 -> 1.7736201
A10: $0.06/kWh @ 60% debt | B10: 0.06 | C10: 0.6 | D10: ='Control Panel & Inputs'!$C$35*$C10 -> 196800000 | E10: ='Control Panel & Inputs'!$C$35-$D10 -> 131200000 | F10: =-PMT('Control Panel & Inputs'!$C$38,'Control Panel & Inputs'!$C$39,$D10) -> 47356877 | G10: =-$E10 -> -131200000 | H10: =B28-IF(1<='Control Panel & Inputs'!$C$39,$F10,0)-MAX(0,B28-IF(1<='Control Panel & Inputs'!$C$41,'Control Panel & Inputs'!$C$35/'Control Panel & Inputs'!$C$41,0)-MIN(IF(1<='Control Panel & Inputs'!$C$39,-IPMT('Control Panel & Inputs'!$C$38,1,'Control Panel & Inputs'!$C$39,$D10),0),'Control Panel & Inputs'!$C$43*B28))*'Control Panel & Inputs'!$C$42 -> 13398673 | I10: =C28-IF(2<='Control Panel & Inputs'!$C$39,$F10,0)-MAX(0,C28-IF(2<='Control Panel & Inputs'!$C$41,'Control Panel & Inputs'!$C$35/'Control Panel & Inputs'!$C$41,0)-MIN(IF(2<='Control Panel & Inputs'!$C$39,-IPMT('Control Panel & Inputs'!$C$38,2,'Control Panel & Inputs'!$C$39,$D10),0),'Control Panel & Inputs'!$C$43*C28))*'Control Panel & Inputs'!$C$42 -> 22968014 | J10: =D28-IF(3<='Control Panel & Inputs'!$C$39,$F10,0)-MAX(0,D28-IF(3<='Control Panel & Inputs'!$C$41,'Control Panel & Inputs'!$C$35/'Control Panel & Inputs'!$C$41,0)-MIN(IF(3<='Control Panel & Inputs'!$C$39,-IPMT('Control Panel & Inputs'!$C$38,3,'Control Panel & Inputs'!$C$39,$D10),0),'Control Panel & Inputs'!$C$43*D28))*'Control Panel & Inputs'!$C$42 -> 24224417 | K10: =E28-IF(4<='Control Panel & Inputs'!$C$39,$F10,0)-MAX(0,E28-IF(4<='Control Panel & Inputs'!$C$41,'Control Panel & Inputs'!$C$35/'Control Panel & Inputs'!$C$41,0)-MIN(IF(4<='Control Panel & Inputs'!$C$39,-IPMT('Control Panel & Inputs'!$C$38,4,'Control Panel & Inputs'!$C$39,$D10),0),'Control Panel & Inputs'!$C$43*E28))*'Control Panel & Inputs'!$C$42 -> 25418337 | L10: =F28-IF(5<='Control Panel & Inputs'!$C$39,$F10,0)-MAX(0,F28-IF(5<='Control Panel & Inputs'!$C$41,'Control Panel & Inputs'!$C$35/'Control Panel & Inputs'!$C$41,0)-MIN(IF(5<='Control Panel & Inputs'!$C$39,-IPMT('Control Panel & Inputs'!$C$38,5,'Control Panel & Inputs'!$C$39,$D10),0),'Control Panel & Inputs'!$C$43*F28))*'Control Panel & Inputs'!$C$42+'Control Panel & Inputs'!$C$35*'Control Panel & Inputs'!$C$36 -> 59292110 | M10: =IRR(G10:L10) -> 0.028591382 | N10: =AVERAGE(B28:F28)/$F10 -> 1.4780167
A11: $0.06/kWh @ 70% debt | B11: 0.06 | C11: 0.7 | D11: ='Control Panel & Inputs'!$C$35*$C11 -> 229600000 | E11: ='Control Panel & Inputs'!$C$35-$D11 -> 98400000 | F11: =-PMT('Control Panel & Inputs'!$C$38,'Control Panel & Inputs'!$C$39,$D11) -> 55249690 | G11: =-$E11 -> -98400000 | H11: =B29-IF(1<='Control Panel & Inputs'!$C$39,$F11,0)-MAX(0,B29-IF(1<='Control Panel & Inputs'!$C$41,'Control Panel & Inputs'!$C$35/'Control Panel & Inputs'!$C$41,0)-MIN(IF(1<='Control Panel & Inputs'!$C$39,-IPMT('Control Panel & Inputs'!$C$38,1,'Control Panel & Inputs'!$C$39,$D11),0),'Control Panel & Inputs'!$C$43*B29))*'Control Panel & Inputs'!$C$42 -> 5505860.5 | I11: =C29-IF(2<='Control Panel & Inputs'!$C$39,$F11,0)-MAX(0,C29-IF(2<='Control Panel & Inputs'!$C$41,'Control Panel & Inputs'!$C$35/'Control Panel & Inputs'!$C$41,0)-MIN(IF(2<='Control Panel & Inputs'!$C$39,-IPMT('Control Panel & Inputs'!$C$38,2,'Control Panel & Inputs'!$C$39,$D11),0),'Control Panel & Inputs'!$C$43*C29))*'Control Panel & Inputs'!$C$42 -> 15075201 | J11: =D29-IF(3<='Control Panel & Inputs'!$C$39,$F11,0)-MAX(0,D29-IF(3<='Control Panel & Inputs'!$C$41,'Control Panel & Inputs'!$C$35/'Control Panel & Inputs'!$C$41,0)-MIN(IF(3<='Control Panel & Inputs'!$C$39,-IPMT('Control Panel & Inputs'!$C$38,3,'Control Panel & Inputs'!$C$39,$D11),0),'Control Panel & Inputs'!$C$43*D29))*'Control Panel & Inputs'!$C$42 -> 16331604 | K11: =E29-IF(4<='Control Panel & Inputs'!$C$39,$F11,0)-MAX(0,E29-IF(4<='Control Panel & Inputs'!$C$41,'Control Panel & Inputs'!$C$35/'Control Panel & Inputs'!$C$41,0)-MIN(IF(4<='Control Panel & Inputs'!$C$39,-IPMT('Control Panel & Inputs'!$C$38,4,'Control Panel & Inputs'!$C$39,$D11),0),'Control Panel & Inputs'!$C$43*E29))*'Control Panel & Inputs'!$C$42 -> 17609587 | L11: =F29-IF(5<='Control Panel & Inputs'!$C$39,$F11,0)-MAX(0,F29-IF(5<='Control Panel & Inputs'!$C$41,'Control Panel & Inputs'!$C$35/'Control Panel & Inputs'!$C$41,0)-MIN(IF(5<='Control Panel & Inputs'!$C$39,-IPMT('Control Panel & Inputs'!$C$38,5,'Control Panel & Inputs'!$C$39,$D11),0),'Control Panel & Inputs'!$C$43*F29))*'Control Panel & Inputs'!$C$42+'Control Panel & Inputs'!$C$35*'Control Panel & Inputs'!$C$36 -> 51442652 | M11: =IRR(G11:L11) -> 0.019298307 | N11: =AVERAGE(B29:F29)/$F11 -> 1.2668715
A12: $0.06/kWh @ 80% debt | B12: 0.06 | C12: 0.8 | D12: ='Control Panel & Inputs'!$C$35*$C12 -> 262400000 | E12: ='Control Panel & Inputs'!$C$35-$D12 -> 65600000 | F12: =-PMT('Control Panel & Inputs'!$C$38,'Control Panel & Inputs'!$C$39,$D12) -> 63142503 | G12: =-$E12 -> -65600000 | H12: =B30-IF(1<='Control Panel & Inputs'!$C$39,$F12,0)-MAX(0,B30-IF(1<='Control Panel & Inputs'!$C$41,'Control Panel & Inputs'!$C$35/'Control Panel & Inputs'!$C$41,0)-MIN(IF(1<='Control Panel & Inputs'!$C$39,-IPMT('Control Panel & Inputs'!$C$38,1,'Control Panel & Inputs'!$C$39,$D12),0),'Control Panel & Inputs'!$C$43*B30))*'Control Panel & Inputs'!$C$42 -> -2386952.3 | I12: =C30-IF(2<='Control Panel & Inputs'!$C$39,$F12,0)-MAX(0,C30-IF(2<='Control Panel & Inputs'!$C$41,'Control Panel & Inputs'!$C$35/'Control Panel & Inputs'!$C$41,0)-MIN(IF(2<='Control Panel & Inputs'!$C$39,-IPMT('Control Panel & Inputs'!$C$38,2,'Control Panel & Inputs'!$C$39,$D12),0),'Control Panel & Inputs'!$C$43*C30))*'Control Panel & Inputs'!$C$42 -> 7182388.7 | J12: =D30-IF(3<='Control Panel & Inputs'!$C$39,$F12,0)-MAX(0,D30-IF(3<='Control Panel & Inputs'!$C$41,'Control Panel & Inputs'!$C$35/'Control Panel & Inputs'!$C$41,0)-MIN(IF(3<='Control Panel & Inputs'!$C$39,-IPMT('Control Panel & Inputs'!$C$38,3,'Control Panel & Inputs'!$C$39,$D12),0),'Control Panel & Inputs'!$C$43*D30))*'Control Panel & Inputs'!$C$42 -> 8438790.9 | K12: =E30-IF(4<='Control Panel & Inputs'!$C$39,$F12,0)-MAX(0,E30-IF(4<='Control Panel & Inputs'!$C$41,'Control Panel & Inputs'!$C$35/'Control Panel & Inputs'!$C$41,0)-MIN(IF(4<='Control Panel & Inputs'!$C$39,-IPMT('Control Panel & Inputs'!$C$38,4,'Control Panel & Inputs'!$C$39,$D12),0),'Control Panel & Inputs'!$C$43*E30))*'Control Panel & Inputs'!$C$42 -> 9788081.3 | L12: =F30-IF(5<='Control Panel & Inputs'!$C$39,$F12,0)-MAX(0,F30-IF(5<='Control Panel & Inputs'!$C$41,'Control Panel & Inputs'!$C$35/'Control Panel & Inputs'!$C$41,0)-MIN(IF(5<='Control Panel & Inputs'!$C$39,-IPMT('Control Panel & Inputs'!$C$38,5,'Control Panel & Inputs'!$C$39,$D12),0),'Control Panel & Inputs'!$C$43*F30))*'Control Panel & Inputs'!$C$42+'Control Panel & Inputs'!$C$35*'Control Panel & Inputs'!$C$36 -> 43593194 | M12: =IRR(G12:L12) -> 0.0034828395 | N12: =AVERAGE(B30:F30)/$F12 -> 1.1085126
A13: $0.08/kWh @ 50% debt | B13: 0.08 | C13: 0.5 | D13: ='Control Panel & Inputs'!$C$35*$C13 -> 164000000 | E13: ='Control Panel & Inputs'!$C$35-$D13 -> 164000000 | F13: =-PMT('Control Panel & Inputs'!$C$38,'Control Panel & Inputs'!$C$39,$D13) -> 39464064 | G13: =-$E13 -> -164000000 | H13: =B31-IF(1<='Control Panel & Inputs'!$C$39,$F13,0)-MAX(0,B31-IF(1<='Control Panel & Inputs'!$C$41,'Control Panel & Inputs'!$C$35/'Control Panel & Inputs'!$C$41,0)-MIN(IF(1<='Control Panel & Inputs'!$C$39,-IPMT('Control Panel & Inputs'!$C$38,1,'Control Panel & Inputs'!$C$39,$D13),0),'Control Panel & Inputs'!$C$43*B31))*'Control Panel & Inputs'!$C$42 -> 19969003 | I13: =C31-IF(2<='Control Panel & Inputs'!$C$39,$F13,0)-MAX(0,C31-IF(2<='Control Panel & Inputs'!$C$41,'Control Panel & Inputs'!$C$35/'Control Panel & Inputs'!$C$41,0)-MIN(IF(2<='Control Panel & Inputs'!$C$39,-IPMT('Control Panel & Inputs'!$C$38,2,'Control Panel & Inputs'!$C$39,$D13),0),'Control Panel & Inputs'!$C$43*C31))*'Control Panel & Inputs'!$C$42 -> 29511894 | J13: =D31-IF(3<='Control Panel & Inputs'!$C$39,$F13,0)-MAX(0,D31-IF(3<='Control Panel & Inputs'!$C$41,'Control Panel & Inputs'!$C$35/'Control Panel & Inputs'!$C$41,0)-MIN(IF(3<='Control Panel & Inputs'!$C$39,-IPMT('Control Panel & Inputs'!$C$38,3,'Control Panel & Inputs'!$C$39,$D13),0),'Control Panel & Inputs'!$C$43*D31))*'Control Panel & Inputs'!$C$42 -> 30741318 | K13: =E31-IF(4<='Control Panel & Inputs'!$C$39,$F13,0)-MAX(0,E31-IF(4<='Control Panel & Inputs'!$C$41,'Control Panel & Inputs'!$C$35/'Control Panel & Inputs'!$C$41,0)-MIN(IF(4<='Control Panel & Inputs'!$C$39,-IPMT('Control Panel & Inputs'!$C$38,4,'Control Panel & Inputs'!$C$39,$D13),0),'Control Panel & Inputs'!$C$43*E31))*'Control Panel & Inputs'!$C$42 -> 31949965 | L13: =F31-IF(5<='Control Panel & Inputs'!$C$39,$F13,0)-MAX(0,F31-IF(5<='Control Panel & Inputs'!$C$41,'Control Panel & Inputs'!$C$35/'Control Panel & Inputs'!$C$41,0)-MIN(IF(5<='Control Panel & Inputs'!$C$39,-IPMT('Control Panel & Inputs'!$C$38,5,'Control Panel & Inputs'!$C$39,$D13),0),'Control Panel & Inputs'!$C$43*F31))*'Control Panel & Inputs'!$C$42+'Control Panel & Inputs'!$C$35*'Control Panel & Inputs'!$C$36 -> 65838904 | M13: =IRR(G13:L13) -> 0.023660595 | N13: =AVERAGE(B31:F31)/$F13 -> 1.7387415
A14: $0.08/kWh @ 60% debt | B14: 0.08 | C14: 0.6 | D14: ='Control Panel & Inputs'!$C$35*$C14 -> 196800000 | E14: ='Control Panel & Inputs'!$C$35-$D14 -> 131200000 | F14: =-PMT('Control Panel & Inputs'!$C$38,'Control Panel & Inputs'!$C$39,$D14) -> 47356877 | G14: =-$E14 -> -131200000 | H14: =B32-IF(1<='Control Panel & Inputs'!$C$39,$F14,0)-MAX(0,B32-IF(1<='Control Panel & Inputs'!$C$41,'Control Panel & Inputs'!$C$35/'Control Panel & Inputs'!$C$41,0)-MIN(IF(1<='Control Panel & Inputs'!$C$39,-IPMT('Control Panel & Inputs'!$C$38,1,'Control Panel & Inputs'!$C$39,$D14),0),'Control Panel & Inputs'!$C$43*B32))*'Control Panel & Inputs'!$C$42 -> 12076190 | I14: =C32-IF(2<='Control Panel & Inputs'!$C$39,$F14,0)-MAX(0,C32-IF(2<='Control Panel & Inputs'!$C$41,'Control Panel & Inputs'!$C$35/'Control Panel & Inputs'!$C$41,0)-MIN(IF(2<='Control Panel & Inputs'!$C$39,-IPMT('Control Panel & Inputs'!$C$38,2,'Control Panel & Inputs'!$C$39,$D14),0),'Control Panel & Inputs'!$C$43*C32))*'Control Panel & Inputs'!$C$42 -> 21619081 | J14: =D32-IF(3<='Control Panel & Inputs'!$C$39,$F14,0)-MAX(0,D32-IF(3<='Control Panel & Inputs'!$C$41,'Control Panel & Inputs'!$C$35/'Control Panel & Inputs'!$C$41,0)-MIN(IF(3<='Control Panel & Inputs'!$C$39,-IPMT('Control Panel & Inputs'!$C$38,3,'Control Panel & Inputs'!$C$39,$D14),0),'Control Panel & Inputs'!$C$43*D32))*'Control Panel & Inputs'!$C$42 -> 22848505 | K14: =E32-IF(4<='Control Panel & Inputs'!$C$39,$F14,0)-MAX(0,E32-IF(4<='Control Panel & Inputs'!$C$41,'Control Panel & Inputs'!$C$35/'Control Panel & Inputs'!$C$41,0)-MIN(IF(4<='Control Panel & Inputs'!$C$39,-IPMT('Control Panel & Inputs'!$C$38,4,'Control Panel & Inputs'!$C$39,$D14),0),'Control Panel & Inputs'!$C$43*E32))*'Control Panel & Inputs'!$C$42 -> 24141215 | L14: =F32-IF(5<='Control Panel & Inputs'!$C$39,$F14,0)-MAX(0,F32-IF(5<='Control Panel & Inputs'!$C$41,'Control Panel & Inputs'!$C$35/'Control Panel & Inputs'!$C$41,0)-MIN(IF(5<='Control Panel & Inputs'!$C$39,-IPMT('Control Panel & Inputs'!$C$38,5,'Control Panel & Inputs'!$C$39,$D14),0),'Control Panel & Inputs'!$C$43*F32))*'Control Panel & Inputs'!$C$42+'Control Panel & Inputs'!$C$35*'Control Panel & Inputs'!$C$36 -> 57989446 | M14: =IRR(G14:L14) -> 0.015228148 | N14: =AVERAGE(B32:F32)/$F14 -> 1.4489512
A15: $0.08/kWh @ 70% debt | B15: 0.08 | C15: 0.7 | D15: ='Control Panel & Inputs'!$C$35*$C15 -> 229600000 | E15: ='Control Panel & Inputs'!$C$35-$D15 -> 98400000 | F15: =-PMT('Control Panel & Inputs'!$C$38,'Control Panel & Inputs'!$C$39,$D15) -> 55249690 | G15: =-$E15 -> -98400000 | H15: =B33-IF(1<='Control Panel & Inputs'!$C$39,$F15,0)-MAX(0,B33-IF(1<='Control Panel & Inputs'!$C$41,'Control Panel & Inputs'!$C$35/'Control Panel & Inputs'!$C$41,0)-MIN(IF(1<='Control Panel & Inputs'!$C$39,-IPMT('Control Panel & Inputs'!$C$38,1,'Control Panel & Inputs'!$C$39,$D15),0),'Control Panel & Inputs'!$C$43*B33))*'Control Panel & Inputs'!$C$42 -> 4183377.3 | I15: =C33-IF(2<='Control Panel & Inputs'!$C$39,$F15,0)-MAX(0,C33-IF(2<='Control Panel & Inputs'!$C$41,'Control Panel & Inputs'!$C$35/'Control Panel & Inputs'!$C$41,0)-MIN(IF(2<='Control Panel & Inputs'!$C$39,-IPMT('Control Panel & Inputs'!$C$38,2,'Control Panel & Inputs'!$C$39,$D15),0),'Control Panel & Inputs'!$C$43*C33))*'Control Panel & Inputs'!$C$42 -> 13726269 | J15: =D33-IF(3<='Control Panel & Inputs'!$C$39,$F15,0)-MAX(0,D33-IF(3<='Control Panel & Inputs'!$C$41,'Control Panel & Inputs'!$C$35/'Control Panel & Inputs'!$C$41,0)-MIN(IF(3<='Control Panel & Inputs'!$C$39,-IPMT('Control Panel & Inputs'!$C$38,3,'Control Panel & Inputs'!$C$39,$D15),0),'Control Panel & Inputs'!$C$43*D33))*'Control Panel & Inputs'!$C$42 -> 14955692 | K15: =E33-IF(4<='Control Panel & Inputs'!$C$39,$F15,0)-MAX(0,E33-IF(4<='Control Panel & Inputs'!$C$41,'Control Panel & Inputs'!$C$35/'Control Panel & Inputs'!$C$41,0)-MIN(IF(4<='Control Panel & Inputs'!$C$39,-IPMT('Control Panel & Inputs'!$C$38,4,'Control Panel & Inputs'!$C$39,$D15),0),'Control Panel & Inputs'!$C$43*E33))*'Control Panel & Inputs'!$C$42 -> 16277464 | L15: =F33-IF(5<='Control Panel & Inputs'!$C$39,$F15,0)-MAX(0,F33-IF(5<='Control Panel & Inputs'!$C$41,'Control Panel & Inputs'!$C$35/'Control Panel & Inputs'!$C$41,0)-MIN(IF(5<='Control Panel & Inputs'!$C$39,-IPMT('Control Panel & Inputs'!$C$38,5,'Control Panel & Inputs'!$C$39,$D15),0),'Control Panel & Inputs'!$C$43*F33))*'Control Panel & Inputs'!$C$42+'Control Panel & Inputs'!$C$35*'Control Panel & Inputs'!$C$36 -> 50139989 | M15: =IRR(G15:L15) -> 0.0022638712 | N15: =AVERAGE(B33:F33)/$F15 -> 1.2419582
A16: $0.08/kWh @ 80% debt | B16: 0.08 | C16: 0.8 | D16: ='Control Panel & Inputs'!$C$35*$C16 -> 262400000 | E16: ='Control Panel & Inputs'!$C$35-$D16 -> 65600000 | F16: =-PMT('Control Panel & Inputs'!$C$38,'Control Panel & Inputs'!$C$39,$D16) -> 63142503 | G16: =-$E16 -> -65600000 | H16: =B34-IF(1<='Control Panel & Inputs'!$C$39,$F16,0)-MAX(0,B34-IF(1<='Control Panel & Inputs'!$C$41,'Control Panel & Inputs'!$C$35/'Control Panel & Inputs'!$C$41,0)-MIN(IF(1<='Control Panel & Inputs'!$C$39,-IPMT('Control Panel & Inputs'!$C$38,1,'Control Panel & Inputs'!$C$39,$D16),0),'Control Panel & Inputs'!$C$43*B34))*'Control Panel & Inputs'!$C$42 -> -3709435.6 | I16: =C34-IF(2<='Control Panel & Inputs'!$C$39,$F16,0)-MAX(0,C34-IF(2<='Control Panel & Inputs'!$C$41,'Control Panel & Inputs'!$C$35/'Control Panel & Inputs'!$C$41,0)-MIN(IF(2<='Control Panel & Inputs'!$C$39,-IPMT('Control Panel & Inputs'!$C$38,2,'Control Panel & Inputs'!$C$39,$D16),0),'Control Panel & Inputs'!$C$43*C34))*'Control Panel & Inputs'!$C$42 -> 5833455.8 | J16: =D34-IF(3<='Control Panel & Inputs'!$C$39,$F16,0)-MAX(0,D34-IF(3<='Control Panel & Inputs'!$C$41,'Control Panel & Inputs'!$C$35/'Control Panel & Inputs'!$C$41,0)-MIN(IF(3<='Control Panel & Inputs'!$C$39,-IPMT('Control Panel & Inputs'!$C$38,3,'Control Panel & Inputs'!$C$39,$D16),0),'Control Panel & Inputs'!$C$43*D34))*'Control Panel & Inputs'!$C$42 -> 7062879.3 | K16: =E34-IF(4<='Control Panel & Inputs'!$C$39,$F16,0)-MAX(0,E34-IF(4<='Control Panel & Inputs'!$C$41,'Control Panel & Inputs'!$C$35/'Control Panel & Inputs'!$C$41,0)-MIN(IF(4<='Control Panel & Inputs'!$C$39,-IPMT('Control Panel & Inputs'!$C$38,4,'Control Panel & Inputs'!$C$39,$D16),0),'Control Panel & Inputs'!$C$43*E34))*'Control Panel & Inputs'!$C$42 -> 8384651.5 | L16: =F34-IF(5<='Control Panel & Inputs'!$C$39,$F16,0)-MAX(0,F34-IF(5<='Control Panel & Inputs'!$C$41,'Control Panel & Inputs'!$C$35/'Control Panel & Inputs'!$C$41,0)-MIN(IF(5<='Control Panel & Inputs'!$C$39,-IPMT('Control Panel & Inputs'!$C$38,5,'Control Panel & Inputs'!$C$39,$D16),0),'Control Panel & Inputs'!$C$43*F34))*'Control Panel & Inputs'!$C$42+'Control Panel & Inputs'!$C$35*'Control Panel & Inputs'!$C$36 -> 42290531 | M16: =IRR(G16:L16) -> -0.019775182 | N16: =AVERAGE(B34:F34)/$F16 -> 1.0867134
... A20: $0.10/kWh @ 80% debt | B20: 0.1 | C20: 0.8 | D20: ='Control Panel & Inputs'!$C$35*$C20 -> 262400000 | E20: ='Control Panel & Inputs'!$C$35-$D20 -> 65600000 | F20: =-PMT('Control Panel & Inputs'!$C$38,'Control Panel & Inputs'!$C$39,$D20) -> 63142503 | G20: =-$E20 -> -65600000 | H20: =B38-IF(1<='Control Panel & Inputs'!$C$39,$F20,0)-MAX(0,B38-IF(1<='Control Panel & Inputs'!$C$41,'Control Panel & Inputs'!$C$35/'Control Panel & Inputs'!$C$41,0)-MIN(IF(1<='Control Panel & Inputs'!$C$39,-IPMT('Control Panel & Inputs'!$C$38,1,'Control Panel & Inputs'!$C$39,$D20),0),'Control Panel & Inputs'!$C$43*B38))*'Control Panel & Inputs'!$C$42 -> -5031918.8 | I20: =C38-IF(2<='Control Panel & Inputs'!$C$39,$F20,0)-MAX(0,C38-IF(2<='Control Panel & Inputs'!$C$41,'Control Panel & Inputs'!$C$35/'Control Panel & Inputs'!$C$41,0)-MIN(IF(2<='Control Panel & Inputs'!$C$39,-IPMT('Control Panel & Inputs'!$C$38,2,'Control Panel & Inputs'!$C$39,$D20),0),'Control Panel & Inputs'!$C$43*C38))*'Control Panel & Inputs'!$C$42 -> 4484522.9 | J20: =D38-IF(3<='Control Panel & Inputs'!$C$39,$F20,0)-MAX(0,D38-IF(3<='Control Panel & Inputs'!$C$41,'Control Panel & Inputs'!$C$35/'Control Panel & Inputs'!$C$41,0)-MIN(IF(3<='Control Panel & Inputs'!$C$39,-IPMT('Control Panel & Inputs'!$C$38,3,'Control Panel & Inputs'!$C$39,$D20),0),'Control Panel & Inputs'!$C$43*D38))*'Control Panel & Inputs'!$C$42 -> 5686967.8 | K20: =E38-IF(4<='Control Panel & Inputs'!$C$39,$F20,0)-MAX(0,E38-IF(4<='Control Panel & Inputs'!$C$41,'Control Panel & Inputs'!$C$35/'Control Panel & Inputs'!$C$41,0)-MIN(IF(4<='Control Panel & Inputs'!$C$39,-IPMT('Control Panel & Inputs'!$C$38,4,'Control Panel & Inputs'!$C$39,$D20),0),'Control Panel & Inputs'!$C$43*E38))*'Control Panel & Inputs'!$C$42 -> 6981221.7 | L20: =F38-IF(5<='Control Panel & Inputs'!$C$39,$F20,0)-MAX(0,F38-IF(5<='Control Panel & Inputs'!$C$41,'Control Panel & Inputs'!$C$35/'Control Panel & Inputs'!$C$41,0)-MIN(IF(5<='Control Panel & Inputs'!$C$39,-IPMT('Control Panel & Inputs'!$C$38,5,'Control Panel & Inputs'!$C$39,$D20),0),'Control Panel & Inputs'!$C$43*F38))*'Control Panel & Inputs'!$C$42+'Control Panel & Inputs'!$C$35*'Control Panel & Inputs'!$C$36 -> 40987867 | M20: =IRR(G20:L20) -> -0.043269535 | N20: =AVERAGE(B38:F38)/$F20 -> 1.0649143
A21: Scenario EBITDA Grid (Year 1-5)
A22: Scenario | B22: Y1 EBITDA | C22: Y2 EBITDA | D22: Y3 EBITDA | E22: Y4 EBITDA | F22: Y5 EBITDA
A23: =A5 -> $0.04/kWh @ 50% debt | B23: ='Pro Forma Financials'!C$8-'Pro Forma Financials'!C$12-'Pro Forma Financials'!C$10*$B5*POWER(1+'Control Panel & Inputs'!$C$34,0) -> 62078034 | C23: ='Pro Forma Financials'!D$8-'Pro Forma Financials'!D$12-'Pro Forma Financials'!C$10*$B5*POWER(1+'Control Panel & Inputs'!$C$34,1) -> 71673824 | D23: ='Pro Forma Financials'!E$8-'Pro Forma Financials'!E$12-'Pro Forma Financials'!C$10*$B5*POWER(1+'Control Panel & Inputs'!$C$34,2) -> 72957205 | E23: ='Pro Forma Financials'!F$8-'Pro Forma Financials'!F$12-'Pro Forma Financials'!C$10*$B5*POWER(1+'Control Panel & Inputs'!$C$34,3) -> 74334014 | F23: ='Pro Forma Financials'!G$8-'Pro Forma Financials'!G$12-'Pro Forma Financials'!C$10*$B5*POWER(1+'Control Panel & Inputs'!$C$34,4) -> 75810463
A24: =A6 -> $0.04/kWh @ 60% debt | B24: ='Pro Forma Financials'!C$8-'Pro Forma Financials'!C$12-'Pro Forma Financials'!C$10*$B6*POWER(1+'Control Panel & Inputs'!$C$34,0) -> 62078034 | C24: ='Pro Forma Financials'!D$8-'Pro Forma Financials'!D$12-'Pro Forma Financials'!C$10*$B6*POWER(1+'Control Panel & Inputs'!$C$34,1) -> 71673824 | D24: ='Pro Forma Financials'!E$8-'Pro Forma Financials'!E$12-'Pro Forma Financials'!C$10*$B6*POWER(1+'Control Panel & Inputs'!$C$34,2) -> 72957205 | E24: ='Pro Forma Financials'!F$8-'Pro Forma Financials'!F$12-'Pro Forma Financials'!C$10*$B6*POWER(1+'Control Panel & Inputs'!$C$34,3) -> 74334014 | F24: ='Pro Forma Financials'!G$8-'Pro Forma Financials'!G$12-'Pro Forma Financials'!C$10*$B6*POWER(1+'Control Panel & Inputs'!$C$34,4) -> 75810463
A25: =A7 -> $0.04/kWh @ 70% debt | B25: ='Pro Forma Financials'!C$8-'Pro Forma Financials'!C$12-'Pro Forma Financials'!C$10*$B7*POWER(1+'Control Panel & Inputs'!$C$34,0) -> 62078034 | C25: ='Pro Forma Financials'!D$8-'Pro Forma Financials'!D$12-'Pro Forma Financials'!C$10*$B7*POWER(1+'Control Panel & Inputs'!$C$34,1) -> 71673824 | D25: ='Pro Forma Financials'!E$8-'Pro Forma Financials'!E$12-'Pro Forma Financials'!C$10*$B7*POWER(1+'Control Panel & Inputs'!$C$34,2) -> 72957205 | E25: ='Pro Forma Financials'!F$8-'Pro Forma Financials'!F$12-'Pro Forma Financials'!C$10*$B7*POWER(1+'Control Panel & Inputs'!$C$34,3) -> 74334014 | F25: ='Pro Forma Financials'!G$8-'Pro Forma Financials'!G$12-'Pro Forma Financials'!C$10*$B7*POWER(1+'Control Panel & Inputs'!$C$34,4) -> 75810463
A26: =A8 -> $0.04/kWh @ 80% debt | B26: ='Pro Forma Financials'!C$8-'Pro Forma Financials'!C$12-'Pro Forma Financials'!C$10*$B8*POWER(1+'Control Panel & Inputs'!$C$34,0) -> 62078034 | C26: ='Pro Forma Financials'!D$8-'Pro Forma Financials'!D$12-'Pro Forma Financials'!C$10*$B8*POWER(1+'Control Panel & Inputs'!$C$34,1) -> 71673824 | D26: ='Pro Forma Financials'!E$8-'Pro Forma Financials'!E$12-'Pro Forma Financials'!C$10*$B8*POWER(1+'Control Panel & Inputs'!$C$34,2) -> 72957205 | E26: ='Pro Forma Financials'!F$8-'Pro Forma Financials'!F$12-'Pro Forma Financials'!C$10*$B8*POWER(1+'Control Panel & Inputs'!$C$34,3) -> 74334014 | F26: ='Pro Forma Financials'!G$8-'Pro Forma Financials'!G$12-'Pro Forma Financials'!C$10*$B8*POWER(1+'Control Panel & Inputs'!$C$34,4) -> 75810463
A27: =A9 -> $0.06/kWh @ 50% debt | B27: ='Pro Forma Financials'!C$8-'Pro Forma Financials'!C$12-'Pro Forma Financials'!C$10*$B9*POWER(1+'Control Panel & Inputs'!$C$34,0) -> 60755550 | C27: ='Pro Forma Financials'!D$8-'Pro Forma Financials'!D$12-'Pro Forma Financials'!C$10*$B9*POWER(1+'Control Panel & Inputs'!$C$34,1) -> 70324891 | D27: ='Pro Forma Financials'!E$8-'Pro Forma Financials'!E$12-'Pro Forma Financials'!C$10*$B9*POWER(1+'Control Panel & Inputs'!$C$34,2) -> 71581294 | E27: ='Pro Forma Financials'!F$8-'Pro Forma Financials'!F$12-'Pro Forma Financials'!C$10*$B9*POWER(1+'Control Panel & Inputs'!$C$34,3) -> 72930584 | F27: ='Pro Forma Financials'!G$8-'Pro Forma Financials'!G$12-'Pro Forma Financials'!C$10*$B9*POWER(1+'Control Panel & Inputs'!$C$34,4) -> 74378964
